Workbook

Sheet Huong dan
A1: ORDER GÓI GIÁ: CHAI & NEBULA (web funnel FunnelFox)
A2: Ngày tạo | B2: 2026-10-05
A3: Phạm vi | B3: 17 funnel: 8 Chai + 9 Nebula, batch funnelfox-upload-2026-10-01 và 2026-10-02
A4: Số SKU cần tạo | B4: =COUNTA(SKU!B4:B11)
A5: trong đó Subscription | B5: =COUNTIF(SKU!E4:E11,"Subscription")
A6: trong đó One-time | B6: =COUNTIF(SKU!E4:E11,"One-time*")
A8: CÁCH ĐIỀN
A9: Ô nền vàng | B9: Ô cần điền. Chỉ điền giá thật mà checkout sẽ thu (USD, số, ví dụ 9.99).
A10: Sheet SKU | B10: Mỗi dòng là một SKU cần tạo trên FunnelFox / Stripe / Paddle. Điền Giá kỳ đầu, Giá gia hạn, Product/Price ID và trạng thái.
A11: Sheet Funnel-Plan | B11: Mỗi dòng là một gói trên paywall của một funnel. Giá tự kéo từ sheet SKU. Điền checkoutUrl rồi dán vào CONFIG.checkoutUrl / CONFIG.offer.checkoutUrl của file HTML.
A12: Sheet Tham khao gia | B12: Giá đối thủ lấy từ research/competitor-pricing-ads-2026-09.xlsx. Chỉ để tham khảo, không copy thang giá.
A13: Chữ xanh dương | B13: Giá đã chốt (bảng giá 2026-10-05). Sửa trực tiếp nếu đổi giá; sheet Funnel-Plan tự cập nhật.
A15: Ví dụ một dòng đã điền | B15: SKU chai_web_1m | Giá kỳ đầu 24.99 | Giá gia hạn 49.99 | $/tuần tự tính 11.54 | Price ID price_1Q... | Trạng thái Đã tạo
A16: Lưu ý funnel | B16: Paywall hiện tại của các funnel đang dùng plan key cũ (weekly/yearly, w1/w4/w12, 1w/4w/12w…). Cần sửa CONFIG.plans của từng file theo sheet Funnel-Plan.
A18: QUY TẮC
A19: Offer one-time | B19: Mọi offer one-time phải là SKU không gia hạn (non-renewing). Không dùng SKU subscription cho offer.
A20: Giá gia hạn | B20: Giá gia hạn luôn hiện cạnh giá intro trên paywall, nên phải điền cả hai cột.
A21: Đếm ngược | B21: Mọi offer để expiresMin = null (không đếm ngược), trừ khi có hạn thật.
A22: Sau thanh toán | B22: Checkout phải redirect về funnel với ?paid=<plan key> hoặc gọi window.IkFunnel.completePurchase(plan).
A23: Hủy gói | B23: Hủy được bằng 1 click.
A25: THÔNG SỐ KHÁC CẦN CHỐT CÙNG GIÁ
A26: Chai: freeMessagesPerDay | B26: 10 (TODO confirm)
A27: Chai: fairUseCap | B27: 300 tin/ngày sau "unlimited" (TODO confirm)
A28: Nebula: refundDays | B28: {{refund_days}}. Nebula base đang dùng 7 ngày, cần xác nhận. Còn là token thì khối hoàn tiền tự ẩn.

Sheet SKU
A1: Danh sách SKU cần tạo (bảng giá chốt 2026-10-05)
A2: Chữ xanh dương = giá đã chốt. Ô vàng còn trống = cần điền (Price ID, trạng thái). $/tuần tự tính từ giá gia hạn.
A3: STT | B3: SKU ID (đề xuất) | C3: App | D3: Tên gói hiển thị | E3: Loại | F3: Chu kỳ gia hạn | G3: Số tuần / chu kỳ | H3: Có giá kỳ đầu (intro)? | I3: Giá kỳ đầu (USD) | J3: Giá gia hạn / giá bán (USD) | K3: $/tuần sau gia hạn | L3: Token trong CONFIG | M3: Dùng ở funnel | N3: Tham khảo giá | O3: Ghi chú | P3: Product / Price ID | Q3: Trạng thái
A4: 1 | B4: chai_web_1m | C4: Chai | D4: 1 month | E4: Subscription | F4: 1 tháng | G4: 4.3333333 | H4: Có | I4: 24.99 | J4: 49.99 | K4: =IF(OR(J4="",G4=""),"",J4/G4) | L4: plans.m1 | M4: Tất cả funnel Chai | N4: Chai App Store: Premium Monthly $13.99 | O4: Tháng đầu $24.99, sau đó $49.99/tháng. | Q4: Chưa tạo
A5: 2 | B5: chai_web_3m | C5: Chai | D5: 3 months | E5: Subscription | F5: 3 tháng | G5: 13 | H5: Có | I5: 49.99 | J5: 109.99 | K5: =IF(OR(J5="",G5=""),"",J5/G5) | L5: plans.m3 | M5: Tất cả funnel Chai | N5: — | O5: Kỳ đầu (3 tháng) $49.99, sau đó $109.99 / 3 tháng. | Q5: Chưa tạo
A6: 3 | B6: chai_web_12m | C6: Chai | D6: 12 months | E6: Subscription | F6: 1 năm | G6: 52 | H6: Có | I6: 119.99 | J6: 299.99 | K6: =IF(OR(J6="",G6=""),"",J6/G6) | L6: plans.y12 | M6: Tất cả funnel Chai | N6: Chai App Store: Premium Annual $134.99 | O6: Năm đầu $119.99, sau đó $299.99/năm. | Q6: Chưa tạo
A7: 4 | B7: chai_web_1m_sale | C7: Chai | D7: 1 month (sale) | E7: Subscription | F7: 1 tháng | G7: 4.3333333 | H7: Có | I7: 22.99 | J7: 49.99 | K7: =IF(OR(J7="",G7=""),"",J7/G7) | L7: offer (sale) | M7: Tất cả funnel Chai | N7: — | O7: Bản sale của 1 month: kỳ đầu $22.99, gia hạn giữ giá gốc $49.99. | Q7: Chưa tạo
A8: 5 | B8: chai_web_3m_sale | C8: Chai | D8: 3 months (sale) | E8: Subscription | F8: 3 tháng | G8: 13 | H8: Có | I8: 44.99 | J8: 109.99 | K8: =IF(OR(J8="",G8=""),"",J8/G8) | L8: offer (sale) | M8: Tất cả funnel Chai | N8: — | O8: Bản sale của 3 months: kỳ đầu $44.99, gia hạn giữ giá gốc $109.99. | Q8: Chưa tạo
A9: 6 | B9: chai_web_12m_sale | C9: Chai | D9: 12 months (sale) | E9: Subscription | F9: 1 năm | G9: 52 | H9: Có | I9: 105.99 | J9: 299.99 | K9: =IF(OR(J9="",G9=""),"",J9/G9) | L9: offer (sale) | M9: Tất cả funnel Chai | N9: — | O9: Bản sale của 12 months: kỳ đầu $105.99, gia hạn giữ giá gốc $299.99. | Q9: Chưa tạo
A10: 7 | B10: chai_lifetime | C10: Chai | D10: Lifetime | E10: One-time (không gia hạn) | F10: — | H10: Không | I10: — | J10: 99.99 | K10: =IF(OR(J10="",G10=""),"",J10/G10) | L10: plans.lifetime (key mới) | M10: Tất cả funnel Chai | N10: — | O10: Trả một lần $99.99, không gia hạn. | Q10: Chưa tạo
A11: 8 | B11: nebula_web_1w_to_1m | C11: Nebula | D11: Tuần đầu → gói tháng | E11: Subscription | F11: 1 tháng (sau tuần đầu) | G11: 4.3333333 | H11: Có | I11: 13.67 | J11: 49.99 | K11: =IF(OR(J11="",G11=""),"",J11/G11) | L11: plans (gói duy nhất) | M11: Tất cả funnel Nebula | N11: Nebula App Store: Premium $2.99–$49.99 | O11: Tuần đầu $13.67, sau đó tự chuyển sang gói tháng $49.99/tháng. | Q11: Chưa tạo

Sheet Funnel-Plan
A1: Gói trên từng funnel → SKU → checkoutUrl
A2: Giá tự kéo từ sheet SKU (chữ xanh lá). Điền checkoutUrl vào ô vàng, rồi dán vào CONFIG của file HTML tương ứng.
A3: App | B3: Funnel | C3: File HTML | D3: Plan key (CONFIG) | E3: SKU ID | F3: Mặc định? | G3: Giá kỳ đầu (USD) | H3: Giá gia hạn (USD) | I3: Loại | J3: checkoutUrl | K3: ?paid= khi redirect về
A4: Chai | B4: chai-ai-boyfriend | C4: funnelfox-upload-2026-10-01/chai/chai-ai-boyfriend.html | D4: m1 | E4: chai_web_1m | G4: =IFERROR(IF(INDEX(SKU!$I$4:$I$11,MATCH($E4,SKU!$B$4:$B$11,0))="","",INDEX(SKU!$I$4:$I$11,MATCH($E4,SKU!$B$4:$B$11,0))),"SKU?") | H4: =IFERROR(IF(INDEX(SKU!$J$4:$J$11,MATCH($E4,SKU!$B$4:$B$11,0))="","",INDEX(SKU!$J$4:$J$11,MATCH($E4,SKU!$B$4:$B$11,0))),"SKU?") | I4: =IFERROR(INDEX(SKU!$E$4:$E$11,MATCH($E4,SKU!$B$4:$B$11,0)),"SKU?") | K4: m1
A5: Chai | B5: chai-ai-boyfriend | C5: funnelfox-upload-2026-10-01/chai/chai-ai-boyfriend.html | D5: m3 | E5: chai_web_3m | G5: =IFERROR(IF(INDEX(SKU!$I$4:$I$11,MATCH($E5,SKU!$B$4:$B$11,0))="","",INDEX(SKU!$I$4:$I$11,MATCH($E5,SKU!$B$4:$B$11,0))),"SKU?") | H5: =IFERROR(IF(INDEX(SKU!$J$4:$J$11,MATCH($E5,SKU!$B$4:$B$11,0))="","",INDEX(SKU!$J$4:$J$11,MATCH($E5,SKU!$B$4:$B$11,0))),"SKU?") | I5: =IFERROR(INDEX(SKU!$E$4:$E$11,MATCH($E5,SKU!$B$4:$B$11,0)),"SKU?") | K5: m3
A6: Chai | B6: chai-ai-boyfriend | C6: funnelfox-upload-2026-10-01/chai/chai-ai-boyfriend.html | D6: y12 | E6: chai_web_12m | F6: Có | G6: =IFERROR(IF(INDEX(SKU!$I$4:$I$11,MATCH($E6,SKU!$B$4:$B$11,0))="","",INDEX(SKU!$I$4:$I$11,MATCH($E6,SKU!$B$4:$B$11,0))),"SKU?") | H6: =IFERROR(IF(INDEX(SKU!$J$4:$J$11,MATCH($E6,SKU!$B$4:$B$11,0))="","",INDEX(SKU!$J$4:$J$11,MATCH($E6,SKU!$B$4:$B$11,0))),"SKU?") | I6: =IFERROR(INDEX(SKU!$E$4:$E$11,MATCH($E6,SKU!$B$4:$B$11,0)),"SKU?") | K6: y12
A7: Chai | B7: chai-ai-boyfriend | C7: funnelfox-upload-2026-10-01/chai/chai-ai-boyfriend.html | D7: offer_m1 | E7: chai_web_1m_sale | G7: =IFERROR(IF(INDEX(SKU!$I$4:$I$11,MATCH($E7,SKU!$B$4:$B$11,0))="","",INDEX(SKU!$I$4:$I$11,MATCH($E7,SKU!$B$4:$B$11,0))),"SKU?") | H7: =IFERROR(IF(INDEX(SKU!$J$4:$J$11,MATCH($E7,SKU!$B$4:$B$11,0))="","",INDEX(SKU!$J$4:$J$11,MATCH($E7,SKU!$B$4:$B$11,0))),"SKU?") | I7: =IFERROR(INDEX(SKU!$E$4:$E$11,MATCH($E7,SKU!$B$4:$B$11,0)),"SKU?") | K7: offer
A8: Chai | B8: chai-ai-boyfriend | C8: funnelfox-upload-2026-10-01/chai/chai-ai-boyfriend.html | D8: offer_m3 | E8: chai_web_3m_sale | G8: =IFERROR(IF(INDEX(SKU!$I$4:$I$11,MATCH($E8,SKU!$B$4:$B$11,0))="","",INDEX(SKU!$I$4:$I$11,MATCH($E8,SKU!$B$4:$B$11,0))),"SKU?") | H8: =IFERROR(IF(INDEX(SKU!$J$4:$J$11,MATCH($E8,SKU!$B$4:$B$11,0))="","",INDEX(SKU!$J$4:$J$11,MATCH($E8,SKU!$B$4:$B$11,0))),"SKU?") | I8: =IFERROR(INDEX(SKU!$E$4:$E$11,MATCH($E8,SKU!$B$4:$B$11,0)),"SKU?") | K8: offer
A9: Chai | B9: chai-ai-boyfriend | C9: funnelfox-upload-2026-10-01/chai/chai-ai-boyfriend.html | D9: offer_y12 | E9: chai_web_12m_sale | G9: =IFERROR(IF(INDEX(SKU!$I$4:$I$11,MATCH($E9,SKU!$B$4:$B$11,0))="","",INDEX(SKU!$I$4:$I$11,MATCH($E9,SKU!$B$4:$B$11,0))),"SKU?") | H9: =IFERROR(IF(INDEX(SKU!$J$4:$J$11,MATCH($E9,SKU!$B$4:$B$11,0))="","",INDEX(SKU!$J$4:$J$11,MATCH($E9,SKU!$B$4:$B$11,0))),"SKU?") | I9: =IFERROR(INDEX(SKU!$E$4:$E$11,MATCH($E9,SKU!$B$4:$B$11,0)),"SKU?") | K9: offer
A10: Chai | B10: chai-ai-boyfriend | C10: funnelfox-upload-2026-10-01/chai/chai-ai-boyfriend.html | D10: lifetime | E10: chai_lifetime | G10: =IFERROR(IF(INDEX(SKU!$I$4:$I$11,MATCH($E10,SKU!$B$4:$B$11,0))="","",INDEX(SKU!$I$4:$I$11,MATCH($E10,SKU!$B$4:$B$11,0))),"SKU?") | H10: =IFERROR(IF(INDEX(SKU!$J$4:$J$11,MATCH($E10,SKU!$B$4:$B$11,0))="","",INDEX(SKU!$J$4:$J$11,MATCH($E10,SKU!$B$4:$B$11,0))),"SKU?") | I10: =IFERROR(INDEX(SKU!$E$4:$E$11,MATCH($E10,SKU!$B$4:$B$11,0)),"SKU?") | K10: lifetime
A11: Chai | B11: chai-companion | C11: funnelfox-upload-2026-10-01/chai/chai-companion.html | D11: m1 | E11: chai_web_1m | G11: =IFERROR(IF(INDEX(SKU!$I$4:$I$11,MATCH($E11,SKU!$B$4:$B$11,0))="","",INDEX(SKU!$I$4:$I$11,MATCH($E11,SKU!$B$4:$B$11,0))),"SKU?") | H11: =IFERROR(IF(INDEX(SKU!$J$4:$J$11,MATCH($E11,SKU!$B$4:$B$11,0))="","",INDEX(SKU!$J$4:$J$11,MATCH($E11,SKU!$B$4:$B$11,0))),"SKU?") | I11: =IFERROR(INDEX(SKU!$E$4:$E$11,MATCH($E11,SKU!$B$4:$B$11,0)),"SKU?") | K11: m1
A12: Chai | B12: chai-companion | C12: funnelfox-upload-2026-10-01/chai/chai-companion.html | D12: m3 | E12: chai_web_3m | G12: =IFERROR(IF(INDEX(SKU!$I$4:$I$11,MATCH($E12,SKU!$B$4:$B$11,0))="","",INDEX(SKU!$I$4:$I$11,MATCH($E12,SKU!$B$4:$B$11,0))),"SKU?") | H12: =IFERROR(IF(INDEX(SKU!$J$4:$J$11,MATCH($E12,SKU!$B$4:$B$11,0))="","",INDEX(SKU!$J$4:$J$11,MATCH($E12,SKU!$B$4:$B$11,0))),"SKU?") | I12: =IFERROR(INDEX(SKU!$E$4:$E$11,MATCH($E12,SKU!$B$4:$B$11,0)),"SKU?") | K12: m3
A13: Chai | B13: chai-companion | C13: funnelfox-upload-2026-10-01/chai/chai-companion.html | D13: y12 | E13: chai_web_12m | F13: Có | G13: =IFERROR(IF(INDEX(SKU!$I$4:$I$11,MATCH($E13,SKU!$B$4:$B$11,0))="","",INDEX(SKU!$I$4:$I$11,MATCH($E13,SKU!$B$4:$B$11,0))),"SKU?") | H13: =IFERROR(IF(INDEX(SKU!$J$4:$J$11,MATCH($E13,SKU!$B$4:$B$11,0))="","",INDEX(SKU!$J$4:$J$11,MATCH($E13,SKU!$B$4:$B$11,0))),"SKU?") | I13: =IFERROR(INDEX(SKU!$E$4:$E$11,MATCH($E13,SKU!$B$4:$B$11,0)),"SKU?") | K13: y12
A14: Chai | B14: chai-companion | C14: funnelfox-upload-2026-10-01/chai/chai-companion.html | D14: offer_m1 | E14: chai_web_1m_sale | G14: =IFERROR(IF(INDEX(SKU!$I$4:$I$11,MATCH($E14,SKU!$B$4:$B$11,0))="","",INDEX(SKU!$I$4:$I$11,MATCH($E14,SKU!$B$4:$B$11,0))),"SKU?") | H14: =IFERROR(IF(INDEX(SKU!$J$4:$J$11,MATCH($E14,SKU!$B$4:$B$11,0))="","",INDEX(SKU!$J$4:$J$11,MATCH($E14,SKU!$B$4:$B$11,0))),"SKU?") | I14: =IFERROR(INDEX(SKU!$E$4:$E$11,MATCH($E14,SKU!$B$4:$B$11,0)),"SKU?") | K14: offer
A15: Chai | B15: chai-companion | C15: funnelfox-upload-2026-10-01/chai/chai-companion.html | D15: offer_m3 | E15: chai_web_3m_sale | G15: =IFERROR(IF(INDEX(SKU!$I$4:$I$11,MATCH($E15,SKU!$B$4:$B$11,0))="","",INDEX(SKU!$I$4:$I$11,MATCH($E15,SKU!$B$4:$B$11,0))),"SKU?") | H15: =IFERROR(IF(INDEX(SKU!$J$4:$J$11,MATCH($E15,SKU!$B$4:$B$11,0))="","",INDEX(SKU!$J$4:$J$11,MATCH($E15,SKU!$B$4:$B$11,0))),"SKU?") | I15: =IFERROR(INDEX(SKU!$E$4:$E$11,MATCH($E15,SKU!$B$4:$B$11,0)),"SKU?") | K15: offer
A16: Chai | B16: chai-companion | C16: funnelfox-upload-2026-10-01/chai/chai-companion.html | D16: offer_y12 | E16: chai_web_12m_sale | G16: =IFERROR(IF(INDEX(SKU!$I$4:$I$11,MATCH($E16,SKU!$B$4:$B$11,0))="","",INDEX(SKU!$I$4:$I$11,MATCH($E16,SKU!$B$4:$B$11,0))),"SKU?") | H16: =IFERROR(IF(INDEX(SKU!$J$4:$J$11,MATCH($E16,SKU!$B$4:$B$11,0))="","",INDEX(SKU!$J$4:$J$11,MATCH($E16,SKU!$B$4:$B$11,0))),"SKU?") | I16: =IFERROR(INDEX(SKU!$E$4:$E$11,MATCH($E16,SKU!$B$4:$B$11,0)),"SKU?") | K16: offer
A17: Chai | B17: chai-companion | C17: funnelfox-upload-2026-10-01/chai/chai-companion.html | D17: lifetime | E17: chai_lifetime | G17: =IFERROR(IF(INDEX(SKU!$I$4:$I$11,MATCH($E17,SKU!$B$4:$B$11,0))="","",INDEX(SKU!$I$4:$I$11,MATCH($E17,SKU!$B$4:$B$11,0))),"SKU?") | H17: =IFERROR(IF(INDEX(SKU!$J$4:$J$11,MATCH($E17,SKU!$B$4:$B$11,0))="","",INDEX(SKU!$J$4:$J$11,MATCH($E17,SKU!$B$4:$B$11,0))),"SKU?") | I17: =IFERROR(INDEX(SKU!$E$4:$E$11,MATCH($E17,SKU!$B$4:$B$11,0)),"SKU?") | K17: lifetime
A18: Chai | B18: chai-romance-stories | C18: funnelfox-upload-2026-10-01/chai/chai-romance-stories.html | D18: m1 | E18: chai_web_1m | G18: =IFERROR(IF(INDEX(SKU!$I$4:$I$11,MATCH($E18,SKU!$B$4:$B$11,0))="","",INDEX(SKU!$I$4:$I$11,MATCH($E18,SKU!$B$4:$B$11,0))),"SKU?") | H18: =IFERROR(IF(INDEX(SKU!$J$4:$J$11,MATCH($E18,SKU!$B$4:$B$11,0))="","",INDEX(SKU!$J$4:$J$11,MATCH($E18,SKU!$B$4:$B$11,0))),"SKU?") | I18: =IFERROR(INDEX(SKU!$E$4:$E$11,MATCH($E18,SKU!$B$4:$B$11,0)),"SKU?") | K18: m1
A19: Chai | B19: chai-romance-stories | C19: funnelfox-upload-2026-10-01/chai/chai-romance-stories.html | D19: m3 | E19: chai_web_3m | G19: =IFERROR(IF(INDEX(SKU!$I$4:$I$11,MATCH($E19,SKU!$B$4:$B$11,0))="","",INDEX(SKU!$I$4:$I$11,MATCH($E19,SKU!$B$4:$B$11,0))),"SKU?") | H19: =IFERROR(IF(INDEX(SKU!$J$4:$J$11,MATCH($E19,SKU!$B$4:$B$11,0))="","",INDEX(SKU!$J$4:$J$11,MATCH($E19,SKU!$B$4:$B$11,0))),"SKU?") | I19: =IFERROR(INDEX(SKU!$E$4:$E$11,MATCH($E19,SKU!$B$4:$B$11,0)),"SKU?") | K19: m3
A20: Chai | B20: chai-romance-stories | C20: funnelfox-upload-2026-10-01/chai/chai-romance-stories.html | D20: y12 | E20: chai_web_12m | F20: Có | G20: =IFERROR(IF(INDEX(SKU!$I$4:$I$11,MATCH($E20,SKU!$B$4:$B$11,0))="","",INDEX(SKU!$I$4:$I$11,MATCH($E20,SKU!$B$4:$B$11,0))),"SKU?") | H20: =IFERROR(IF(INDEX(SKU!$J$4:$J$11,MATCH($E20,SKU!$B$4:$B$11,0))="","",INDEX(SKU!$J$4:$J$11,MATCH($E20,SKU!$B$4:$B$11,0))),"SKU?") | I20: =IFERROR(INDEX(SKU!$E$4:$E$11,MATCH($E20,SKU!$B$4:$B$11,0)),"SKU?") | K20: y12
A21: Chai | B21: chai-romance-stories | C21: funnelfox-upload-2026-10-01/chai/chai-romance-stories.html | D21: offer_m1 | E21: chai_web_1m_sale | G21: =IFERROR(IF(INDEX(SKU!$I$4:$I$11,MATCH($E21,SKU!$B$4:$B$11,0))="","",INDEX(SKU!$I$4:$I$11,MATCH($E21,SKU!$B$4:$B$11,0))),"SKU?") | H21: =IFERROR(IF(INDEX(SKU!$J$4:$J$11,MATCH($E21,SKU!$B$4:$B$11,0))="","",INDEX(SKU!$J$4:$J$11,MATCH($E21,SKU!$B$4:$B$11,0))),"SKU?") | I21: =IFERROR(INDEX(SKU!$E$4:$E$11,MATCH($E21,SKU!$B$4:$B$11,0)),"SKU?") | K21: offer
A22: Chai | B22: chai-romance-stories | C22: funnelfox-upload-2026-10-01/chai/chai-romance-stories.html | D22: offer_m3 | E22: chai_web_3m_sale | G22: =IFERROR(IF(INDEX(SKU!$I$4:$I$11,MATCH($E22,SKU!$B$4:$B$11,0))="","",INDEX(SKU!$I$4:$I$11,MATCH($E22,SKU!$B$4:$B$11,0))),"SKU?") | H22: =IFERROR(IF(INDEX(SKU!$J$4:$J$11,MATCH($E22,SKU!$B$4:$B$11,0))="","",INDEX(SKU!$J$4:$J$11,MATCH($E22,SKU!$B$4:$B$11,0))),"SKU?") | I22: =IFERROR(INDEX(SKU!$E$4:$E$11,MATCH($E22,SKU!$B$4:$B$11,0)),"SKU?") | K22: offer
A23: Chai | B23: chai-romance-stories | C23: funnelfox-upload-2026-10-01/chai/chai-romance-stories.html | D23: offer_y12 | E23: chai_web_12m_sale | G23: =IFERROR(IF(INDEX(SKU!$I$4:$I$11,MATCH($E23,SKU!$B$4:$B$11,0))="","",INDEX(SKU!$I$4:$I$11,MATCH($E23,SKU!$B$4:$B$11,0))),"SKU?") | H23: =IFERROR(IF(INDEX(SKU!$J$4:$J$11,MATCH($E23,SKU!$B$4:$B$11,0))="","",INDEX(SKU!$J$4:$J$11,MATCH($E23,SKU!$B$4:$B$11,0))),"SKU?") | I23: =IFERROR(INDEX(SKU!$E$4:$E$11,MATCH($E23,SKU!$B$4:$B$11,0)),"SKU?") | K23: offer
A24: Chai | B24: chai-romance-stories | C24: funnelfox-upload-2026-10-01/chai/chai-romance-stories.html | D24: lifetime | E24: chai_lifetime | G24: =IFERROR(IF(INDEX(SKU!$I$4:$I$11,MATCH($E24,SKU!$B$4:$B$11,0))="","",INDEX(SKU!$I$4:$I$11,MATCH($E24,SKU!$B$4:$B$11,0))),"SKU?") | H24: =IFERROR(IF(INDEX(SKU!$J$4:$J$11,MATCH($E24,SKU!$B$4:$B$11,0))="","",INDEX(SKU!$J$4:$J$11,MATCH($E24,SKU!$B$4:$B$11,0))),"SKU?") | I24: =IFERROR(INDEX(SKU!$E$4:$E$11,MATCH($E24,SKU!$B$4:$B$11,0)),"SKU?") | K24: lifetime
A25: Chai | B25: chai-ai-girlfriend | C25: funnelfox-upload-2026-10-01/chai/chai-ai-girlfriend.html | D25: m1 | E25: chai_web_1m | G25: =IFERROR(IF(INDEX(SKU!$I$4:$I$11,MATCH($E25,SKU!$B$4:$B$11,0))="","",INDEX(SKU!$I$4:$I$11,MATCH($E25,SKU!$B$4:$B$11,0))),"SKU?") | H25: =IFERROR(IF(INDEX(SKU!$J$4:$J$11,MATCH($E25,SKU!$B$4:$B$11,0))="","",INDEX(SKU!$J$4:$J$11,MATCH($E25,SKU!$B$4:$B$11,0))),"SKU?") | I25: =IFERROR(INDEX(SKU!$E$4:$E$11,MATCH($E25,SKU!$B$4:$B$11,0)),"SKU?") | K25: m1
A26: Chai | B26: chai-ai-girlfriend | C26: funnelfox-upload-2026-10-01/chai/chai-ai-girlfriend.html | D26: m3 | E26: chai_web_3m | G26: =IFERROR(IF(INDEX(SKU!$I$4:$I$11,MATCH($E26,SKU!$B$4:$B$11,0))="","",INDEX(SKU!$I$4:$I$11,MATCH($E26,SKU!$B$4:$B$11,0))),"SKU?") | H26: =IFERROR(IF(INDEX(SKU!$J$4:$J$11,MATCH($E26,SKU!$B$4:$B$11,0))="","",INDEX(SKU!$J$4:$J$11,MATCH($E26,SKU!$B$4:$B$11,0))),"SKU?") | I26: =IFERROR(INDEX(SKU!$E$4:$E$11,MATCH($E26,SKU!$B$4:$B$11,0)),"SKU?") | K26: m3
A27: Chai | B27: chai-ai-girlfriend | C27: funnelfox-upload-2026-10-01/chai/chai-ai-girlfriend.html | D27: y12 | E27: chai_web_12m | F27: Có | G27: =IFERROR(IF(INDEX(SKU!$I$4:$I$11,MATCH($E27,SKU!$B$4:$B$11,0))="","",INDEX(SKU!$I$4:$I$11,MATCH($E27,SKU!$B$4:$B$11,0))),"SKU?") | H27: =IFERROR(IF(INDEX(SKU!$J$4:$J$11,MATCH($E27,SKU!$B$4:$B$11,0))="","",INDEX(SKU!$J$4:$J$11,MATCH($E27,SKU!$B$4:$B$11,0))),"SKU?") | I27: =IFERROR(INDEX(SKU!$E$4:$E$11,MATCH($E27,SKU!$B$4:$B$11,0)),"SKU?") | K27: y12
A28: Chai | B28: chai-ai-girlfriend | C28: funnelfox-upload-2026-10-01/chai/chai-ai-girlfriend.html | D28: offer_m1 | E28: chai_web_1m_sale | G28: =IFERROR(IF(INDEX(SKU!$I$4:$I$11,MATCH($E28,SKU!$B$4:$B$11,0))="","",INDEX(SKU!$I$4:$I$11,MATCH($E28,SKU!$B$4:$B$11,0))),"SKU?") | H28: =IFERROR(IF(INDEX(SKU!$J$4:$J$11,MATCH($E28,SKU!$B$4:$B$11,0))="","",INDEX(SKU!$J$4:$J$11,MATCH($E28,SKU!$B$4:$B$11,0))),"SKU?") | I28: =IFERROR(INDEX(SKU!$E$4:$E$11,MATCH($E28,SKU!$B$4:$B$11,0)),"SKU?") | K28: offer
A29: Chai | B29: chai-ai-girlfriend | C29: funnelfox-upload-2026-10-01/chai/chai-ai-girlfriend.html | D29: offer_m3 | E29: chai_web_3m_sale | G29: =IFERROR(IF(INDEX(SKU!$I$4:$I$11,MATCH($E29,SKU!$B$4:$B$11,0))="","",INDEX(SKU!$I$4:$I$11,MATCH($E29,SKU!$B$4:$B$11,0))),"SKU?") | H29: =IFERROR(IF(INDEX(SKU!$J$4:$J$11,MATCH($E29,SKU!$B$4:$B$11,0))="","",INDEX(SKU!$J$4:$J$11,MATCH($E29,SKU!$B$4:$B$11,0))),"SKU?") | I29: =IFERROR(INDEX(SKU!$E$4:$E$11,MATCH($E29,SKU!$B$4:$B$11,0)),"SKU?") | K29: offer
A30: Chai | B30: chai-ai-girlfriend | C30: funnelfox-upload-2026-10-01/chai/chai-ai-girlfriend.html | D30: offer_y12 | E30: chai_web_12m_sale | G30: =IFERROR(IF(INDEX(SKU!$I$4:$I$11,MATCH($E30,SKU!$B$4:$B$11,0))="","",INDEX(SKU!$I$4:$I$11,MATCH($E30,SKU!$B$4:$B$11,0))),"SKU?") | H30: =IFERROR(IF(INDEX(SKU!$J$4:$J$11,MATCH($E30,SKU!$B$4:$B$11,0))="","",INDEX(SKU!$J$4:$J$11,MATCH($E30,SKU!$B$4:$B$11,0))),"SKU?") | I30: =IFERROR(INDEX(SKU!$E$4:$E$11,MATCH($E30,SKU!$B$4:$B$11,0)),"SKU?") | K30: offer
A31: Chai | B31: chai-ai-girlfriend | C31: funnelfox-upload-2026-10-01/chai/chai-ai-girlfriend.html | D31: lifetime | E31: chai_lifetime | G31: =IFERROR(IF(INDEX(SKU!$I$4:$I$11,MATCH($E31,SKU!$B$4:$B$11,0))="","",INDEX(SKU!$I$4:$I$11,MATCH($E31,SKU!$B$4:$B$11,0))),"SKU?") | H31: =IFERROR(IF(INDEX(SKU!$J$4:$J$11,MATCH($E31,SKU!$B$4:$B$11,0))="","",INDEX(SKU!$J$4:$J$11,MATCH($E31,SKU!$B$4:$B$11,0))),"SKU?") | I31: =IFERROR(INDEX(SKU!$E$4:$E$11,MATCH($E31,SKU!$B$4:$B$11,0)),"SKU?") | K31: lifetime
A32: Chai | B32: chai-dream-girl | C32: funnelfox-upload-2026-10-01/chai/chai-dream-girl.html | D32: m1 | E32: chai_web_1m | G32: =IFERROR(IF(INDEX(SKU!$I$4:$I$11,MATCH($E32,SKU!$B$4:$B$11,0))="","",INDEX(SKU!$I$4:$I$11,MATCH($E32,SKU!$B$4:$B$11,0))),"SKU?") | H32: =IFERROR(IF(INDEX(SKU!$J$4:$J$11,MATCH($E32,SKU!$B$4:$B$11,0))="","",INDEX(SKU!$J$4:$J$11,MATCH($E32,SKU!$B$4:$B$11,0))),"SKU?") | I32: =IFERROR(INDEX(SKU!$E$4:$E$11,MATCH($E32,SKU!$B$4:$B$11,0)),"SKU?") | K32: m1
A33: Chai | B33: chai-dream-girl | C33: funnelfox-upload-2026-10-01/chai/chai-dream-girl.html | D33: m3 | E33: chai_web_3m | G33: =IFERROR(IF(INDEX(SKU!$I$4:$I$11,MATCH($E33,SKU!$B$4:$B$11,0))="","",INDEX(SKU!$I$4:$I$11,MATCH($E33,SKU!$B$4:$B$11,0))),"SKU?") | H33: =IFERROR(IF(INDEX(SKU!$J$4:$J$11,MATCH($E33,SKU!$B$4:$B$11,0))="","",INDEX(SKU!$J$4:$J$11,MATCH($E33,SKU!$B$4:$B$11,0))),"SKU?") | I33: =IFERROR(INDEX(SKU!$E$4:$E$11,MATCH($E33,SKU!$B$4:$B$11,0)),"SKU?") | K33: m3
A34: Chai | B34: chai-dream-girl | C34: funnelfox-upload-2026-10-01/chai/chai-dream-girl.html | D34: y12 | E34: chai_web_12m | F34: Có | G34: =IFERROR(IF(INDEX(SKU!$I$4:$I$11,MATCH($E34,SKU!$B$4:$B$11,0))="","",INDEX(SKU!$I$4:$I$11,MATCH($E34,SKU!$B$4:$B$11,0))),"SKU?") | H34: =IFERROR(IF(INDEX(SKU!$J$4:$J$11,MATCH($E34,SKU!$B$4:$B$11,0))="","",INDEX(SKU!$J$4:$J$11,MATCH($E34,SKU!$B$4:$B$11,0))),"SKU?") | I34: =IFERROR(INDEX(SKU!$E$4:$E$11,MATCH($E34,SKU!$B$4:$B$11,0)),"SKU?") | K34: y12
A35: Chai | B35: chai-dream-girl | C35: funnelfox-upload-2026-10-01/chai/chai-dream-girl.html | D35: offer_m1 | E35: chai_web_1m_sale | G35: =IFERROR(IF(INDEX(SKU!$I$4:$I$11,MATCH($E35,SKU!$B$4:$B$11,0))="","",INDEX(SKU!$I$4:$I$11,MATCH($E35,SKU!$B$4:$B$11,0))),"SKU?") | H35: =IFERROR(IF(INDEX(SKU!$J$4:$J$11,MATCH($E35,SKU!$B$4:$B$11,0))="","",INDEX(SKU!$J$4:$J$11,MATCH($E35,SKU!$B$4:$B$11,0))),"SKU?") | I35: =IFERROR(INDEX(SKU!$E$4:$E$11,MATCH($E35,SKU!$B$4:$B$11,0)),"SKU?") | K35: offer
A36: Chai | B36: chai-dream-girl | C36: funnelfox-upload-2026-10-01/chai/chai-dream-girl.html | D36: offer_m3 | E36: chai_web_3m_sale | G36: =IFERROR(IF(INDEX(SKU!$I$4:$I$11,MATCH($E36,SKU!$B$4:$B$11,0))="","",INDEX(SKU!$I$4:$I$11,MATCH($E36,SKU!$B$4:$B$11,0))),"SKU?") | H36: =IFERROR(IF(INDEX(SKU!$J$4:$J$11,MATCH($E36,SKU!$B$4:$B$11,0))="","",INDEX(SKU!$J$4:$J$11,MATCH($E36,SKU!$B$4:$B$11,0))),"SKU?") | I36: =IFERROR(INDEX(SKU!$E$4:$E$11,MATCH($E36,SKU!$B$4:$B$11,0)),"SKU?") | K36: offer
A37: Chai | B37: chai-dream-girl | C37: funnelfox-upload-2026-10-01/chai/chai-dream-girl.html | D37: offer_y12 | E37: chai_web_12m_sale | G37: =IFERROR(IF(INDEX(SKU!$I$4:$I$11,MATCH($E37,SKU!$B$4:$B$11,0))="","",INDEX(SKU!$I$4:$I$11,MATCH($E37,SKU!$B$4:$B$11,0))),"SKU?") | H37: =IFERROR(IF(INDEX(SKU!$J$4:$J$11,MATCH($E37,SKU!$B$4:$B$11,0))="","",INDEX(SKU!$J$4:$J$11,MATCH($E37,SKU!$B$4:$B$11,0))),"SKU?") | I37: =IFERROR(INDEX(SKU!$E$4:$E$11,MATCH($E37,SKU!$B$4:$B$11,0)),"SKU?") | K37: offer
A38: Chai | B38: chai-dream-girl | C38: funnelfox-upload-2026-10-01/chai/chai-dream-girl.html | D38: lifetime | E38: chai_lifetime | G38: =IFERROR(IF(INDEX(SKU!$I$4:$I$11,MATCH($E38,SKU!$B$4:$B$11,0))="","",INDEX(SKU!$I$4:$I$11,MATCH($E38,SKU!$B$4:$B$11,0))),"SKU?") | H38: =IFERROR(IF(INDEX(SKU!$J$4:$J$11,MATCH($E38,SKU!$B$4:$B$11,0))="","",INDEX(SKU!$J$4:$J$11,MATCH($E38,SKU!$B$4:$B$11,0))),"SKU?") | I38: =IFERROR(INDEX(SKU!$E$4:$E$11,MATCH($E38,SKU!$B$4:$B$11,0)),"SKU?") | K38: lifetime
A39: Chai | B39: chai-named-character | C39: funnelfox-upload-2026-10-02/chai/chai-named-character.html | D39: m1 | E39: chai_web_1m | G39: =IFERROR(IF(INDEX(SKU!$I$4:$I$11,MATCH($E39,SKU!$B$4:$B$11,0))="","",INDEX(SKU!$I$4:$I$11,MATCH($E39,SKU!$B$4:$B$11,0))),"SKU?") | H39: =IFERROR(IF(INDEX(SKU!$J$4:$J$11,MATCH($E39,SKU!$B$4:$B$11,0))="","",INDEX(SKU!$J$4:$J$11,MATCH($E39,SKU!$B$4:$B$11,0))),"SKU?") | I39: =IFERROR(INDEX(SKU!$E$4:$E$11,MATCH($E39,SKU!$B$4:$B$11,0)),"SKU?") | K39: m1
A40: Chai | B40: chai-named-character | C40: funnelfox-upload-2026-10-02/chai/chai-named-character.html | D40: m3 | E40: chai_web_3m | G40: =IFERROR(IF(INDEX(SKU!$I$4:$I$11,MATCH($E40,SKU!$B$4:$B$11,0))="","",INDEX(SKU!$I$4:$I$11,MATCH($E40,SKU!$B$4:$B$11,0))),"SKU?") | H40: =IFERROR(IF(INDEX(SKU!$J$4:$J$11,MATCH($E40,SKU!$B$4:$B$11,0))="","",INDEX(SKU!$J$4:$J$11,MATCH($E40,SKU!$B$4:$B$11,0))),"SKU?") | I40: =IFERROR(INDEX(SKU!$E$4:$E$11,MATCH($E40,SKU!$B$4:$B$11,0)),"SKU?") | K40: m3
...

Sheet Tham khao gia
A1: Giá tham khảo đối thủ (nguồn: funnel/research/competitor-pricing-ads-2026-09.xlsx, sheet "Gói giá")
A3: Brand | B3: Kênh | C3: Gói | D3: Giá | E3: Tiền tệ | F3: Ghi chú
A4: Chai | B4: App Store US | C4: Premium Membership | D4: 9.99 | E4: USD
A5: Chai | B5: App Store US | C5: Premium Monthly | D5: 13.99 | E5: USD
A6: Chai | B6: App Store US | C6: Premium Annual | D6: 134.99 | E6: USD
A7: Chai | B7: App Store US | C7: Ultra Weekly | D7: 19.99 | E7: USD
A8: Chai | B8: App Store US | C8: Ultra Monthly | D8: 29.99 | E8: USD
A9: Chai | B9: App Store US | C9: Ultra Annual | D9: 269.99 | E9: USD
A10: Chai | B10: App Store US | C10: 200 Pieces (lẻ) | D10: 2.79 | E10: USD
A11: Chai | B11: App Store US | C11: 500 Pieces (lẻ) | D11: 6.99 | E11: USD
A12: ChatChi (base) | B12: Funnel nội bộ | C12: Weekly | D12: 6.99 | E12: USD | F12: Đang hard-code trong 3 funnel Chai
A13: ChatChi (base) | B13: Funnel nội bộ | C13: Yearly | D13: 99.99 | E13: USD | F13: Đang hard-code trong 3 funnel Chai
A14: Nebula | B14: App Store US | C14: Premium (các mức) | D14: 2.99 | E14: USD | F14: Các mức: 2.99 / 7.99 / 29.99 / 39.99 / 49.99
A15: Nebula | B15: App Store US | C15: Chat Balance | D15: 9.99 | E15: USD
A16: Nebula | B16: App Store US | C16: Daily secrets (lẻ) | D16: 7.99 | E16: USD
A17: Nebula | B17: App Store US | C17: Relationship Check-In (lẻ) | D17: 4.99 | E17: USD
A18: Hint | B18: Web funnel | C18: Trial 7 ngày | D18: 1 | E18: EUR | F18: Giá gia hạn không hiện
A19: Hint | B19: Web funnel | C19: Báo cáo phụ (upsell) | D19: 3 | E19: EUR | F19: Astrocartography, Soulmate Sketch…
